distributed.nanny - INFO -         Start Nanny at: 'tcp://172.16.37.158:37872'
distributed.worker - INFO -       Start worker at:  tcp://172.16.37.158:35607
distributed.worker - INFO -          Listening to:  tcp://172.16.37.158:35607
distributed.worker - INFO -          dashboard at:        172.16.37.158:44971
distributed.worker - INFO - Waiting to connect to:    tcp://172.16.33.2:45818
distributed.worker - INFO - -------------------------------------------------
distributed.worker - INFO -               Threads:                         45
distributed.worker - INFO -                Memory:                  93.13 GiB
distributed.worker - INFO -       Local Directory: /gpfs/work/machnitz/dask_storage/dask-worker-space/worker-ig7aw29s
distributed.worker - INFO - -------------------------------------------------
distributed.worker - INFO -         Registered to:    tcp://172.16.33.2:45818
distributed.worker - INFO - -------------------------------------------------
distributed.core - INFO - Starting established connection
distributed.worker - WARNING - Compute Failed
Function:  costly_simulation
args:      (array([0.30225927, 0.80039959, 0.80968044, 0.78941927]))
kwargs:    {}
Exception: NameError("name 'random' is not defined")

distributed.worker - WARNING - Compute Failed
Function:  costly_simulation
args:      (array([0.73924599, 0.05124317, 0.45447478, 0.48191802]))
kwargs:    {}
Exception: NameError("name 'random' is not defined")

distributed.worker - WARNING - Compute Failed
Function:  costly_simulation
args:      (array([0.13281265, 0.05005626, 0.80092635, 0.04209368]))
kwargs:    {}
Exception: NameError("name 'random' is not defined")

distributed.worker - WARNING - Compute Failed
Function:  costly_simulation
args:      (array([0.41968412, 0.80339409, 0.6469305 , 0.95867548]))
kwargs:    {}
Exception: NameError("name 'random' is not defined")

distributed.worker - WARNING - Compute Failed
Function:  costly_simulation
args:      (array([0.38290734, 0.38665988, 0.0442532 , 0.31542297]))
kwargs:    {}
Exception: NameError("name 'random' is not defined")

distributed.worker - WARNING - Compute Failed
Function:  costly_simulation
args:      (array([0.09117979, 0.97129229, 0.34327973, 0.58934954]))
kwargs:    {}
Exception: NameError("name 'random' is not defined")

distributed.worker - WARNING - Compute Failed
Function:  costly_simulation
args:      (array([0.49501196, 0.7210809 , 0.21329481, 0.24624007]))
kwargs:    {}
Exception: NameError("name 'random' is not defined")

distributed.worker - WARNING - Compute Failed
Function:  costly_simulation
args:      (array([0.65467102, 0.1614289 , 0.03856193, 0.91297368]))
kwargs:    {}
Exception: NameError("name 'random' is not defined")

distributed.worker - WARNING - Compute Failed
Function:  costly_simulation
args:      (array([0.6733907 , 0.65109795, 0.13202974, 0.49988888]))
kwargs:    {}
Exception: NameError("name 'random' is not defined")

distributed.worker - WARNING - Compute Failed
Function:  costly_simulation
args:      (array([0.76799664, 0.75373243, 0.52471318, 0.18578359]))
kwargs:    {}
Exception: NameError("name 'random' is not defined")

tornado.application - ERROR - Exception in callback <bound method SystemMonitor.update of <SystemMonitor: cpu: 31 memory: 124 MB fds: 22>>
Traceback (most recent call last):
  File "/gpfs/home/machnitz/miniconda3/envs/plankton/lib/python3.7/site-packages/tornado/ioloop.py", line 905, in _run
    return self.callback()
  File "/gpfs/home/machnitz/miniconda3/envs/plankton/lib/python3.7/site-packages/distributed/system_monitor.py", line 96, in update
    gpu_extra = nvml.one_time()
  File "/gpfs/home/machnitz/miniconda3/envs/plankton/lib/python3.7/site-packages/distributed/diagnostics/nvml.py", line 45, in one_time
    h = _pynvml_handles()
  File "/gpfs/home/machnitz/miniconda3/envs/plankton/lib/python3.7/site-packages/distributed/diagnostics/nvml.py", line 20, in _pynvml_handles
    count = pynvml.nvmlDeviceGetCount()
  File "/gpfs/home/machnitz/miniconda3/envs/plankton/lib/python3.7/site-packages/pynvml.py", line 797, in nvmlDeviceGetCount
    fn = _nvmlGetFunctionPointer("nvmlDeviceGetCount_v2")
  File "/gpfs/home/machnitz/miniconda3/envs/plankton/lib/python3.7/site-packages/pynvml.py", line 325, in _nvmlGetFunctionPointer
    raise NVMLError(NVML_ERROR_UNINITIALIZED)
pynvml.NVMLError_Uninitialized: Uninitialized
tornado.application - ERROR - Exception in callback <bound method SystemMonitor.update of <SystemMonitor: cpu: 6 memory: 124 MB fds: 22>>
Traceback (most recent call last):
  File "/gpfs/home/machnitz/miniconda3/envs/plankton/lib/python3.7/site-packages/tornado/ioloop.py", line 905, in _run
    return self.callback()
  File "/gpfs/home/machnitz/miniconda3/envs/plankton/lib/python3.7/site-packages/distributed/system_monitor.py", line 96, in update
    gpu_extra = nvml.one_time()
  File "/gpfs/home/machnitz/miniconda3/envs/plankton/lib/python3.7/site-packages/distributed/diagnostics/nvml.py", line 45, in one_time
    h = _pynvml_handles()
  File "/gpfs/home/machnitz/miniconda3/envs/plankton/lib/python3.7/site-packages/distributed/diagnostics/nvml.py", line 20, in _pynvml_handles
    count = pynvml.nvmlDeviceGetCount()
  File "/gpfs/home/machnitz/miniconda3/envs/plankton/lib/python3.7/site-packages/pynvml.py", line 797, in nvmlDeviceGetCount
    fn = _nvmlGetFunctionPointer("nvmlDeviceGetCount_v2")
  File "/gpfs/home/machnitz/miniconda3/envs/plankton/lib/python3.7/site-packages/pynvml.py", line 325, in _nvmlGetFunctionPointer
    raise NVMLError(NVML_ERROR_UNINITIALIZED)
pynvml.NVMLError_Uninitialized: Uninitialized
tornado.application - ERROR - Exception in callback <bound method SystemMonitor.update of <SystemMonitor: cpu: 4 memory: 124 MB fds: 23>>
Traceback (most recent call last):
  File "/gpfs/home/machnitz/miniconda3/envs/plankton/lib/python3.7/site-packages/tornado/ioloop.py", line 905, in _run
    return self.callback()
  File "/gpfs/home/machnitz/miniconda3/envs/plankton/lib/python3.7/site-packages/distributed/system_monitor.py", line 96, in update
    gpu_extra = nvml.one_time()
  File "/gpfs/home/machnitz/miniconda3/envs/plankton/lib/python3.7/site-packages/distributed/diagnostics/nvml.py", line 45, in one_time
    h = _pynvml_handles()
  File "/gpfs/home/machnitz/miniconda3/envs/plankton/lib/python3.7/site-packages/distributed/diagnostics/nvml.py", line 20, in _pynvml_handles
    count = pynvml.nvmlDeviceGetCount()
  File "/gpfs/home/machnitz/miniconda3/envs/plankton/lib/python3.7/site-packages/pynvml.py", line 797, in nvmlDeviceGetCount
    fn = _nvmlGetFunctionPointer("nvmlDeviceGetCount_v2")
  File "/gpfs/home/machnitz/miniconda3/envs/plankton/lib/python3.7/site-packages/pynvml.py", line 325, in _nvmlGetFunctionPointer
    raise NVMLError(NVML_ERROR_UNINITIALIZED)
pynvml.NVMLError_Uninitialized: Uninitialized
tornado.application - ERROR - Exception in callback <bound method SystemMonitor.update of <SystemMonitor: cpu: 4 memory: 124 MB fds: 23>>
Traceback (most recent call last):
  File "/gpfs/home/machnitz/miniconda3/envs/plankton/lib/python3.7/site-packages/tornado/ioloop.py", line 905, in _run
    return self.callback()
  File "/gpfs/home/machnitz/miniconda3/envs/plankton/lib/python3.7/site-packages/distributed/system_monitor.py", line 96, in update
    gpu_extra = nvml.one_time()
  File "/gpfs/home/machnitz/miniconda3/envs/plankton/lib/python3.7/site-packages/distributed/diagnostics/nvml.py", line 45, in one_time
    h = _pynvml_handles()
  File "/gpfs/home/machnitz/miniconda3/envs/plankton/lib/python3.7/site-packages/distributed/diagnostics/nvml.py", line 20, in _pynvml_handles
    count = pynvml.nvmlDeviceGetCount()
  File "/gpfs/home/machnitz/miniconda3/envs/plankton/lib/python3.7/site-packages/pynvml.py", line 797, in nvmlDeviceGetCount
    fn = _nvmlGetFunctionPointer("nvmlDeviceGetCount_v2")
  File "/gpfs/home/machnitz/miniconda3/envs/plankton/lib/python3.7/site-packages/pynvml.py", line 325, in _nvmlGetFunctionPointer
    raise NVMLError(NVML_ERROR_UNINITIALIZED)
pynvml.NVMLError_Uninitialized: Uninitialized
distributed.worker - INFO - Stopping worker at tcp://172.16.37.158:35607
distributed.nanny - INFO - Worker closed
slurmstepd: error: *** JOB 524405 ON n158 CANCELLED AT 2021-06-15T09:42:01 ***
slurmstepd: error: task_p_post_term: rmdir(/dev/cpuset/slurm524405/slurm524405.4294967294_0) failed Device or resource busy
